Workbook
Name Slicer_Category: #N/A
Name Slicer_Category1: #N/A
Name Slicer_Category2: #N/A
Name Slicer_Category3: #N/A
Name Slicer_Customer_Name: #N/A
Name Slicer_Product: #N/A
Name Slicer_Product1: #N/A
Name Slicer_State: #N/A
Name Slicer_State1: #N/A

Sheet Sales_data
A1: Order_ID | B1: Order_Date | C1: Customer_Name | D1: State | E1: Category | F1: Product | G1: Sales | H1: Quantity | I1: Profit
A2: ORD001 | B2: 46027 | C2: Arun | D2: Tamil Nadu | E2: Electronics | F2: Laptop | G2: 55000 | H2: 2 | I2: 7000
A3: ORD002 | B3: 46029 | C3: Priya | D3: Kerala | E3: Furniture | F3: Office Chair | G3: 12000 | H3: 3 | I3: 2400
A4: ORD003 | B4: 46032 | C4: Ravi | D4: Karnataka | E4: Electronics | F4: Mobile | G4: 30000 | H4: 3 | I4: 4500
A5: ORD004 | B5: 46035 | C5: Divya | D5: Telangana | E5: Stationery | F5: Notebook | G5: 2500 | H5: 10 | I5: 500
A6: ORD005 | B6: 46038 | C6: Karthik | D6: Tamil Nadu | E6: Electronics | F6: Mouse | G6: 2400 | H6: 6 | I6: 480
A7: ORD006 | B7: 46042 | C7: Meena | D7: Kerala | E7: Furniture | F7: Desk | G7: 18000 | H7: 2 | I7: 3600
A8: ORD007 | B8: 46045 | C8: Suresh | D8: Karnataka | E8: Electronics | F8: Keyboard | G8: 4500 | H8: 5 | I8: 900
A9: ORD008 | B9: 46049 | C9: Anitha | D9: Telangana | E9: Stationery | F9: Pen | G9: 1200 | H9: 20 | I9: 240
A10: ORD009 | B10: 46055 | C10: Vimal | D10: Tamil Nadu | E10: Electronics | F10: Monitor | G10: 28000 | H10: 2 | I10: 4200
A11: ORD010 | B11: 46058 | C11: Kavya | D11: Kerala | E11: Furniture | F11: Bookshelf | G11: 15000 | H11: 2 | I11: 3000
A12: ORD011 | B12: 46061 | C12: Arun | D12: Karnataka | E12: Electronics | F12: Laptop | G12: 60000 | H12: 2 | I12: 8000
A13: ORD012 | B13: 46065 | C13: Priya | D13: Telangana | E13: Stationery | F13: Notebook | G13: 3000 | H13: 12 | I13: 600
... A51: ORD050 | B51: 46195 | C51: Kavya | D51: Kerala | E51: Furniture | F51: Office Chair | G51: 28000 | H51: 7 | I51: 5600

Sheet Analysis
A1: SUM | D1: IF,AND,OR | N1: LOOKUPS | P1: DATA CLEANING | R1: DYNAMIC ARRAY FUNCTIONS | T1: SORT()
A2: Total Sales | B2: =SUM(Sales_data!G2:G51) -> 1074600 | D2: If Profit is greater than or equal to ₹5,000, show "High Profit", otherwise show "Low Profit". | E2: {=IF(Sales_data!I2:I51>=5000,"HIGH PROFIT","LOW")} -> HIGH PROFIT | F2: {=IF(Sales_data!G2:G51>30000,"GOOD SALES","LOW")} -> GOOD SALES | G2: {=IF(Sales_data!H2:H51>=5,"BULK","NORMAL")} -> NORMAL | H2: =IF(AND(Sales_data!G2>30000,Sales_data!I2>5000),"HIGH","NRML") -> HIGH | I2: =IF(AND(Sales_data!H2>=5,Sales_data!I2>=1000),"BEST","REGURAL") -> REGURAL | J2: =IF(OR(Sales_data!D2="TAMILNADU",Sales_data!D2="KERALA"),"IMPORTANT","OTHER STATE") -> OTHER STATE | K2: =IF(OR(Sales_data!G2>50000,Sales_data!I2>7000),"TOP","NORMAL") -> TOP | L2: =IF(OR(AND(Sales_data!G2>40000,Sales_data!I2>6000),Sales_data!H2>=10),"HIGH PRIORITY") -> HIGH PRIORITY | N2: Q1. Find the Category for | P2: In Sales_data , check whether the Customer_Name in C2 is blank.(ISBLANK)
A3: Total Quantity | B3: =SUM(Sales_data!H2:H51) -> 429 | D3: If Sales is greater than ₹30,000, show "Good Sales", otherwise "Low Sales" | E3: LOW | F3: LOW | G3: NORMAL | H3: =IF(AND(Sales_data!G3>30000,Sales_data!I3>5000),"HIGH","NRML") -> NRML | I3: =IF(AND(Sales_data!H3>=5,Sales_data!I3>=1000),"BEST","REGURAL") -> REGURAL | J3: =IF(OR(Sales_data!D3="TAMILNADU",Sales_data!D3="KERALA"),"IMPORTANT","OTHER STATE") -> IMPORTANT | K3: =IF(OR(Sales_data!G3>50000,Sales_data!I3>7000),"TOP","NORMAL") -> NORMAL | L3: =IF(OR(AND(Sales_data!G3>40000,Sales_data!I3>6000),Sales_data!H3>=10),"HIGH PRIORITY") -> FALSE | N3: Laptop | P3: =ISBLANK(Sales_data!C2) -> FALSE | R3: From your Sales_data sheet, find all unique Categories from E2:E51. UNIQUE() | T3: Sort the Sales values from Sales_data!G2:G51
A4: Total Profit | B4: =SUM(Sales_data!I2:I51) -> 173520 | D4: If Quantity is greater than or equal to 5, show "Bulk Order", otherwise "Normal Order". | E4: LOW | F4: LOW | G4: NORMAL | H4: =IF(AND(Sales_data!G4>30000,Sales_data!I4>5000),"HIGH","NRML") -> NRML | I4: =IF(AND(Sales_data!H4>=5,Sales_data!I4>=1000),"BEST","REGURAL") -> REGURAL | J4: =IF(OR(Sales_data!D4="TAMILNADU",Sales_data!D4="KERALA"),"IMPORTANT","OTHER STATE") -> OTHER STATE | K4: =IF(OR(Sales_data!G4>50000,Sales_data!I4>7000),"TOP","NORMAL") -> NORMAL | L4: =IF(OR(AND(Sales_data!G4>40000,Sales_data!I4>6000),Sales_data!H4>=10),"HIGH PRIORITY") -> FALSE | N4: =_xlfn.XLOOKUP(N3,Sales_data!F2:F51,Sales_data!E2:E51,"NIL") -> Electronics | R4: {=_xlfn.UNIQUE(Sales_data!E2:E51,FALSE)} -> Electronics | T4: in ascending order (smallest → largest).
A5: AVERAGE | D5: High Value Order | E5: LOW | F5: LOW | G5: BULK | H5: =IF(AND(Sales_data!G5>30000,Sales_data!I5>5000),"HIGH","NRML") -> NRML | I5: =IF(AND(Sales_data!H5>=5,Sales_data!I5>=1000),"BEST","REGURAL") -> REGURAL | J5: =IF(OR(Sales_data!D5="TAMILNADU",Sales_data!D5="KERALA"),"IMPORTANT","OTHER STATE") -> OTHER STATE | K5: =IF(OR(Sales_data!G5>50000,Sales_data!I5>7000),"TOP","NORMAL") -> NORMAL | L5: =IF(OR(AND(Sales_data!G5>40000,Sales_data!I5>6000),Sales_data!H5>=10),"HIGH PRIORITY") -> HIGH PRIORITY | P5: Your State column may contain extra spaces.(TRIM) | R5: Furniture | T5: ==SORT(Sales_data!A2:I51,7,1)
A6: Average Sales | B6: =AVERAGE(Sales_data!G2:G51) -> 21492 | D6: Show "High Value" if: | E6: LOW | F6: LOW | G6: BULK | H6: =IF(AND(Sales_data!G6>30000,Sales_data!I6>5000),"HIGH","NRML") -> NRML | I6: =IF(AND(Sales_data!H6>=5,Sales_data!I6>=1000),"BEST","REGURAL") -> REGURAL | J6: =IF(OR(Sales_data!D6="TAMILNADU",Sales_data!D6="KERALA"),"IMPORTANT","OTHER STATE") -> OTHER STATE | K6: =IF(OR(Sales_data!G6>50000,Sales_data!I6>7000),"TOP","NORMAL") -> NORMAL | L6: =IF(OR(AND(Sales_data!G6>40000,Sales_data!I6>6000),Sales_data!H6>=10),"HIGH PRIORITY") -> FALSE | N6: If Laptop | P6: =TRIM(Sales_data!D2) -> Tamil Nadu | R6: Stationery
A7: Average Profit | B7: =AVERAGE(Sales_data!I2:I51) -> 3470.4 | D7: Sales > ₹30,000 AND | E7: LOW | F7: LOW | G7: NORMAL | H7: =IF(AND(Sales_data!G7>30000,Sales_data!I7>5000),"HIGH","NRML") -> NRML | I7: =IF(AND(Sales_data!H7>=5,Sales_data!I7>=1000),"BEST","REGURAL") -> REGURAL | J7: =IF(OR(Sales_data!D7="TAMILNADU",Sales_data!D7="KERALA"),"IMPORTANT","OTHER STATE") -> IMPORTANT | K7: =IF(OR(Sales_data!G7>50000,Sales_data!I7>7000),"TOP","NORMAL") -> NORMAL | L7: =IF(OR(AND(Sales_data!G7>40000,Sales_data!I7>6000),Sales_data!H7>=10),"HIGH PRIORITY") -> FALSE | N7: contains a Product name, use XLOOKUP to find the Sales amount for that product. | T7: Sort the entire
A8: Average Quantity | B8: =AVERAGE(Sales_data!H2:H51) -> 8.58 | D8: Profit > ₹5,000 | E8: LOW | F8: LOW | G8: BULK | H8: =IF(AND(Sales_data!G8>30000,Sales_data!I8>5000),"HIGH","NRML") -> NRML | I8: =IF(AND(Sales_data!H8>=5,Sales_data!I8>=1000),"BEST","REGURAL") -> REGURAL | J8: =IF(OR(Sales_data!D8="TAMILNADU",Sales_data!D8="KERALA"),"IMPORTANT","OTHER STATE") -> OTHER STATE | K8: =IF(OR(Sales_data!G8>50000,Sales_data!I8>7000),"TOP","NORMAL") -> NORMAL | L8: =IF(OR(AND(Sales_data!G8>40000,Sales_data!I8>6000),Sales_data!H8>=10),"HIGH PRIORITY") -> FALSE | P8: Remove extra spaces from D15: | R8: Find all unique States from Sales_data!D2:D51 | T8: Sales_data
A9: COUNT | D9: Otherwise show "Normal" | E9: LOW | F9: LOW | G9: BULK | H9: =IF(AND(Sales_data!G9>30000,Sales_data!I9>5000),"HIGH","NRML") -> NRML | I9: =IF(AND(Sales_data!H9>=5,Sales_data!I9>=1000),"BEST","REGURAL") -> REGURAL | J9: =IF(OR(Sales_data!D9="TAMILNADU",Sales_data!D9="KERALA"),"IMPORTANT","OTHER STATE") -> OTHER STATE | K9: =IF(OR(Sales_data!G9>50000,Sales_data!I9>7000),"TOP","NORMAL") -> NORMAL | L9: =IF(OR(AND(Sales_data!G9>40000,Sales_data!I9>6000),Sales_data!H9>=10),"HIGH PRIORITY") -> HIGH PRIORITY | N9: =_xlfn.XLOOKUP(N3,Sales_data!F2:F51,Sales_data!G2:G51,"NIL") -> 55000 | P9: =TRIM(Sales_data!D15) -> Kerala | R9: {=_xlfn.UNIQUE(Sales_data!D2:D51,FALSE)} -> Tamil Nadu | T9: table by Profit, from highest to lowest.
A10: Number of Orders | B10: =COUNTA(Sales_data!A2:A51) -> 50 | E10: LOW | F10: LOW | G10: NORMAL | H10: =IF(AND(Sales_data!G10>30000,Sales_data!I10>5000),"HIGH","NRML") -> NRML | I10: =IF(AND(Sales_data!H10>=5,Sales_data!I10>=1000),"BEST","REGURAL") -> REGURAL | J10: =IF(OR(Sales_data!D10="TAMILNADU",Sales_data!D10="KERALA"),"IMPORTANT","OTHER STATE") -> OTHER STATE | K10: =IF(OR(Sales_data!G10>50000,Sales_data!I10>7000),"TOP","NORMAL") -> NORMAL | L10: =IF(OR(AND(Sales_data!G10>40000,Sales_data!I10>6000),Sales_data!H10>=10),"HIGH PRIORITY") -> FALSE | R10: Kerala | T10: ==SORT(Sales_data!A2:I51,9,-1)
A11: Number of Sales values | B11: =COUNT(Sales_data!G2:G51) -> 50 | D11: Bulk & Profitable Order | E11: LOW | F11: LOW | G11: NORMAL | H11: =IF(AND(Sales_data!G11>30000,Sales_data!I11>5000),"HIGH","NRML") -> NRML | I11: =IF(AND(Sales_data!H11>=5,Sales_data!I11>=1000),"BEST","REGURAL") -> REGURAL | J11: =IF(OR(Sales_data!D11="TAMILNADU",Sales_data!D11="KERALA"),"IMPORTANT","OTHER STATE") -> IMPORTANT | K11: =IF(OR(Sales_data!G11>50000,Sales_data!I11>7000),"TOP","NORMAL") -> NORMAL | L11: =IF(OR(AND(Sales_data!G11>40000,Sales_data!I11>6000),Sales_data!H11>=10),"HIGH PRIORITY") -> FALSE | N11: If Laptop | P11: From Order_ID in A10, extract the first 3 characters.(LEFT()) | R11: Karnataka
A12: MAX / MIN | D12: Show "Best Order" if: | E12: HIGH PROFIT | F12: GOOD SALES | G12: NORMAL | H12: =IF(AND(Sales_data!G12>30000,Sales_data!I12>5000),"HIGH","NRML") -> HIGH | I12: =IF(AND(Sales_data!H12>=5,Sales_data!I12>=1000),"BEST","REGURAL") -> REGURAL | J12: =IF(OR(Sales_data!D12="TAMILNADU",Sales_data!D12="KERALA"),"IMPORTANT","OTHER STATE") -> OTHER STATE | K12: =IF(OR(Sales_data!G12>50000,Sales_data!I12>7000),"TOP","NORMAL") -> TOP | L12: =IF(OR(AND(Sales_data!G12>40000,Sales_data!I12>6000),Sales_data!H12>=10),"HIGH PRIORITY") -> HIGH PRIORITY | N12: contains a Product name, find the Profit for that product. | P12: =LEFT(Sales_data!A10,3) -> ORD | R12: Telangana | T12: Sort the entire table by Quantity, from highest → lowest.
A13: Highest Sales | B13: =MAX(Sales_data!G2:G51) -> 90000 | D13: Quantity >= 5 AND | E13: LOW | F13: LOW | G13: BULK | H13: =IF(AND(Sales_data!G13>30000,Sales_data!I13>5000),"HIGH","NRML") -> NRML | I13: =IF(AND(Sales_data!H13>=5,Sales_data!I13>=1000),"BEST","REGURAL") -> REGURAL | J13: =IF(OR(Sales_data!D13="TAMILNADU",Sales_data!D13="KERALA"),"IMPORTANT","OTHER STATE") -> OTHER STATE | K13: =IF(OR(Sales_data!G13>50000,Sales_data!I13>7000),"TOP","NORMAL") -> NORMAL | L13: =IF(OR(AND(Sales_data!G13>40000,Sales_data!I13>6000),Sales_data!H13>=10),"HIGH PRIORITY") -> HIGH PRIORITY | T13: ==SORT(Sales_data!A2:I51,8,-1)
A14: Lowest Sales | B14: =MIN(Sales_data!G2:G51) -> 1200 | D14: Profit >= ₹1,000 | E14: HIGH PROFIT | F14: GOOD SALES | G14: NORMAL | H14: =IF(AND(Sales_data!G14>30000,Sales_data!I14>5000),"HIGH","NRML") -> HIGH | I14: =IF(AND(Sales_data!H14>=5,Sales_data!I14>=1000),"BEST","REGURAL") -> REGURAL | J14: =IF(OR(Sales_data!D14="TAMILNADU",Sales_data!D14="KERALA"),"IMPORTANT","OTHER STATE") -> OTHER STATE | K14: =IF(OR(Sales_data!G14>50000,Sales_data!I14>7000),"TOP","NORMAL") -> NORMAL | L14: =IF(OR(AND(Sales_data!G14>40000,Sales_data!I14>6000),Sales_data!H14>=10),"HIGH PRIORITY") -> FALSE | N14: =_xlfn.XLOOKUP(N3,Sales_data!F2:F51,Sales_data!I2:I51,"NIL") -> 7000 | P14: From Order_ID in A20, extract the last 3 characters.(RIGHT())
A15: Highest Profit | B15: =MAX(Sales_data!I2:I51) -> 12000 | D15: Otherwise show "Regular Order". | E15: LOW | F15: LOW | G15: NORMAL | H15: =IF(AND(Sales_data!G15>30000,Sales_data!I15>5000),"HIGH","NRML") -> NRML | I15: =IF(AND(Sales_data!H15>=5,Sales_data!I15>=1000),"BEST","REGURAL") -> REGURAL | J15: =IF(OR(Sales_data!D15="TAMILNADU",Sales_data!D15="KERALA"),"IMPORTANT","OTHER STATE") -> IMPORTANT | K15: =IF(OR(Sales_data!G15>50000,Sales_data!I15>7000),"TOP","NORMAL") -> NORMAL | L15: =IF(OR(AND(Sales_data!G15>40000,Sales_data!I15>6000),Sales_data!H15>=10),"HIGH PRIORITY") -> FALSE | P15: =RIGHT(Sales_data!A20,3) -> 019 | R15: FILTER() | T15: Sort the entire table by Order_Date, from oldest → newest.
A16: Lowest Profit | B16: =MIN(Sales_data!I2:I51) -> 240 | E16: LOW | F16: LOW | G16: BULK | H16: =IF(AND(Sales_data!G16>30000,Sales_data!I16>5000),"HIGH","NRML") -> NRML | I16: =IF(AND(Sales_data!H16>=5,Sales_data!I16>=1000),"BEST","REGURAL") -> REGURAL | J16: =IF(OR(Sales_data!D16="TAMILNADU",Sales_data!D16="KERALA"),"IMPORTANT","OTHER STATE") -> OTHER STATE | K16: =IF(OR(Sales_data!G16>50000,Sales_data!I16>7000),"TOP","NORMAL") -> NORMAL | L16: =IF(OR(AND(Sales_data!G16>40000,Sales_data!I16>6000),Sales_data!H16>=10),"HIGH PRIORITY") -> FALSE | N16: . Find the Sales for Order ID ORD015. | R16: Find all rows where the Category is "Electronics". | T16: ==SORT(Sales_data!A2:I51,2,1)
A17: Basic arithmetic | D17: Show "Important" if the State is Tamil Nadu OR Kerala. Otherwise show "Other State". | E17: LOW | F17: LOW | G17: BULK | H17: =IF(AND(Sales_data!G17>30000,Sales_data!I17>5000),"HIGH","NRML") -> NRML | I17: =IF(AND(Sales_data!H17>=5,Sales_data!I17>=1000),"BEST","REGURAL") -> REGURAL | J17: =IF(OR(Sales_data!D17="TAMILNADU",Sales_data!D17="KERALA"),"IMPORTANT","OTHER STATE") -> OTHER STATE | K17: =IF(OR(Sales_data!G17>50000,Sales_data!I17>7000),"TOP","NORMAL") -> NORMAL | L17: =IF(OR(AND(Sales_data!G17>40000,Sales_data!I17>6000),Sales_data!H17>=10),"HIGH PRIORITY") -> HIGH PRIORITY | N17: =VLOOKUP(Sales_data!A16,Sales_data!A2:I51,7,FALSE) -> 3200 | P17: From Order_ID in A25, extract the middle 3 characters.(MID()) | R17: {=_xlfn._xlws.FILTER(Sales_data!F2:F51,Sales_data!E2:E51="Electronics")} -> Laptop
A18: Sales ÷ Orders | B18: =B2/B10 -> 21492 | E18: LOW | F18: LOW | G18: BULK | H18: =IF(AND(Sales_data!G18>30000,Sales_data!I18>5000),"HIGH","NRML") -> NRML | I18: =IF(AND(Sales_data!H18>=5,Sales_data!I18>=1000),"BEST","REGURAL") -> BEST | J18: =IF(OR(Sales_data!D18="TAMILNADU",Sales_data!D18="KERALA"),"IMPORTANT","OTHER STATE") -> OTHER STATE | K18: =IF(OR(Sales_data!G18>50000,Sales_data!I18>7000),"TOP","NORMAL") -> NORMAL | L18: =IF(OR(AND(Sales_data!G18>40000,Sales_data!I18>6000),Sales_data!H18>=10),"HIGH PRIORITY") -> FALSE | N18: Find the Customer Name for Order ID ORD030. | P18: =MID(Sales_data!A25,2,3) -> RD0 | R18: Mobile | T18: Sort the entire
A19: Highest Sales − Lowest Sales | B19: =B13-B14 -> 88800 | D19: High Sales or High Profit | E19: LOW | F19: LOW | G19: NORMAL | H19: =IF(AND(Sales_data!G19>30000,Sales_data!I19>5000),"HIGH","NRML") -> NRML | I19: =IF(AND(Sales_data!H19>=5,Sales_data!I19>=1000),"BEST","REGURAL") -> REGURAL | J19: =IF(OR(Sales_data!D19="TAMILNADU",Sales_data!D19="KERALA"),"IMPORTANT","OTHER STATE") -> IMPORTANT | K19: =IF(OR(Sales_data!G19>50000,Sales_data!I19>7000),"TOP","NORMAL") -> NORMAL | L19: =IF(OR(AND(Sales_data!G19>40000,Sales_data!I19>6000),Sales_data!H19>=10),"HIGH PRIORITY") -> FALSE | N19: =VLOOKUP(Sales_data!A31,Sales_data!A2:I51,3,FALSE) -> Kavya | R19: Mouse | T19: Sales_data
D20: Show "Top Performance" if: | E20: HIGH PROFIT | F20: GOOD SALES | G20: NORMAL | H20: =IF(AND(Sales_data!G20>30000,Sales_data!I20>5000),"HIGH","NRML") -> HIGH | I20: =IF(AND(Sales_data!H20>=5,Sales_data!I20>=1000),"BEST","REGURAL") -> REGURAL | J20: =IF(OR(Sales_data!D20="TAMILNADU",Sales_data!D20="KERALA"),"IMPORTANT","OTHER STATE") -> OTHER STATE | K20: =IF(OR(Sales_data!G20>50000,Sales_data!I20>7000),"TOP","NORMAL") -> NORMAL | L20: =IF(OR(AND(Sales_data!G20>40000,Sales_data!I20>6000),Sales_data!H20>=10),"HIGH PRIORITY") -> FALSE | P20: TEXT FUNCTIONS | R20: Keyboard | T20: table by Sales, highest → lowest.
D21: Sales > ₹50,000 OR | E21: LOW | F21: LOW | G21: BULK | H21: =IF(AND(Sales_data!G21>30000,Sales_data!I21>5000),"HIGH","NRML") -> NRML | I21: =IF(AND(Sales_data!H21>=5,Sales_data!I21>=1000),"BEST","REGURAL") -> REGURAL | J21: =IF(OR(Sales_data!D21="TAMILNADU",Sales_data!D21="KERALA"),"IMPORTANT","OTHER STATE") -> OTHER STATE | K21: =IF(OR(Sales_data!G21>50000,Sales_data!I21>7000),"TOP","NORMAL") -> NORMAL | L21: =IF(OR(AND(Sales_data!G21>40000,Sales_data!I21>6000),Sales_data!H21>=10),"HIGH PRIORITY") -> FALSE | P21: Combine the Customer_Name (C2) and State (D2) with a space between them. CONCAT() | R21: Monitor | T21: ==SORT(Sales_data!A2:I51,7,-1)
D22: Profit > ₹7,000 | E22: HIGH PROFIT | F22: GOOD SALES | G22: NORMAL | H22: =IF(AND(Sales_data!G22>30000,Sales_data!I22>5000),"HIGH","NRML") -> HIGH | I22: =IF(AND(Sales_data!H22>=5,Sales_data!I22>=1000),"BEST","REGURAL") -> REGURAL | J22: =IF(OR(Sales_data!D22="TAMILNADU",Sales_data!D22="KERALA"),"IMPORTANT","OTHER STATE") -> OTHER STATE | K22: =IF(OR(Sales_data!G22>50000,Sales_data!I22>7000),"TOP","NORMAL") -> TOP | L22: =IF(OR(AND(Sales_data!G22>40000,Sales_data!I22>6000),Sales_data!H22>=10),"HIGH PRIORITY") -> HIGH PRIORITY | N22: Find the Quantity for Order ID ORD045 | P22: =_xlfn.CONCAT(Sales_data!C2," ",Sales_data!D2) -> Arun Tamil Nadu | R22: Laptop
D23: Otherwise show "Normal Performance" | E23: LOW | F23: LOW | G23: NORMAL | H23: =IF(AND(Sales_data!G23>30000,Sales_data!I23>5000),"HIGH","NRML") -> NRML | I23: =IF(AND(Sales_data!H23>=5,Sales_data!I23>=1000),"BEST","REGURAL") -> REGURAL | J23: =IF(OR(Sales_data!D23="TAMILNADU",Sales_data!D23="KERALA"),"IMPORTANT","OTHER STATE") -> IMPORTANT | K23: =IF(OR(Sales_data!G23>50000,Sales_data!I23>7000),"TOP","NORMAL") -> NORMAL | L23: =IF(OR(AND(Sales_data!G23>40000,Sales_data!I23>6000),Sales_data!H23>=10),"HIGH PRIORITY") -> FALSE | R23: Mobile | T23: Sort the entire table by Profit, lowest → highest.
E24: HIGH PROFIT | F24: GOOD SALES | G24: BULK | H24: =IF(AND(Sales_data!G24>30000,Sales_data!I24>5000),"HIGH","NRML") -> HIGH | I24: =IF(AND(Sales_data!H24>=5,Sales_data!I24>=1000),"BEST","REGURAL") -> BEST | J24: =IF(OR(Sales_data!D24="TAMILNADU",Sales_data!D24="KERALA"),"IMPORTANT","OTHER STATE") -> OTHER STATE | K24: =IF(OR(Sales_data!G24>50000,Sales_data!I24>7000),"TOP","NORMAL") -> TOP | L24: =IF(OR(AND(Sales_data!G24>40000,Sales_data!I24>6000),Sales_data!H24>=10),"HIGH PRIORITY") -> HIGH PRIORITY | N24: =VLOOKUP(Sales_data!A6,Sales_data!A2:I51,8,FALSE) -> 6 | P24: Combine Product (F5) and Category (E5) with " - " between them. | R24: Mouse | T24: ==SORT(Sales_data!A2:I51,'Sales_data'!I2:I51,1)
D25: If (Sales > ₹40,000 AND Profit > ₹6,000) OR Quantity >= 10, show "HIGH PRIORITY". | E25: LOW | F25: LOW | G25: BULK | H25: =IF(AND(Sales_data!G25>30000,Sales_data!I25>5000),"HIGH","NRML") -> NRML | I25: =IF(AND(Sales_data!H25>=5,Sales_data!I25>=1000),"BEST","REGURAL") -> REGURAL | J25: =IF(OR(Sales_data!D25="TAMILNADU",Sales_data!D25="KERALA"),"IMPORTANT","OTHER STATE") -> OTHER STATE | K25: =IF(OR(Sales_data!G25>50000,Sales_data!I25>7000),"TOP","NORMAL") -> NORMAL | L25: =IF(OR(AND(Sales_data!G25>40000,Sales_data!I25>6000),Sales_data!H25>=10),"HIGH PRIORITY") -> HIGH PRIORITY | P25: =_xlfn.CONCAT(Sales_data!E2,"-",Sales_data!F2) -> Electronics-Laptop | R25: Keyboard
E26: LOW | F26: LOW | G26: BULK | H26: =IF(AND(Sales_data!G26>30000,Sales_data!I26>5000),"HIGH","NRML") -> NRML | I26: =IF(AND(Sales_data!H26>=5,Sales_data!I26>=1000),"BEST","REGURAL") -> REGURAL | J26: =IF(OR(Sales_data!D26="TAMILNADU",Sales_data!D26="KERALA"),"IMPORTANT","OTHER STATE") -> OTHER STATE | K26: =IF(OR(Sales_data!G26>50000,Sales_data!I26>7000),"TOP","NORMAL") -> NORMAL | L26: =IF(OR(AND(Sales_data!G26>40000,Sales_data!I26>6000),Sales_data!H26>=10),"HIGH PRIORITY") -> HIGH PRIORITY | R26: Monitor | T26: FILTER + SORT
A27: 1️⃣ SUMIF — Practice | E27: LOW | F27: LOW | G27: BULK | H27: =IF(AND(Sales_data!G27>30000,Sales_data!I27>5000),"HIGH","NRML") -> NRML | I27: =IF(AND(Sales_data!H27>=5,Sales_data!I27>=1000),"BEST","REGURAL") -> BEST | J27: =IF(OR(Sales_data!D27="TAMILNADU",Sales_data!D27="KERALA"),"IMPORTANT","OTHER STATE") -> IMPORTANT | K27: =IF(OR(Sales_data!G27>50000,Sales_data!I27>7000),"TOP","NORMAL") -> NORMAL | L27: =IF(OR(AND(Sales_data!G27>40000,Sales_data!I27>6000),Sales_data!H27>=10),"HIGH PRIORITY") -> FALSE | P27: TEXTJOIN() | R27: Laptop | T27: Find all Product names where Category = "Electronics" and sort them by Sales from highest → lowest.
A28: Q1. Find the total Sales for Electronics. | E28: LOW | F28: LOW | G28: BULK | H28: =IF(AND(Sales_data!G28>30000,Sales_data!I28>5000),"HIGH","NRML") -> NRML | I28: =IF(AND(Sales_data!H28>=5,Sales_data!I28>=1000),"BEST","REGURAL") -> BEST | J28: =IF(OR(Sales_data!D28="TAMILNADU",Sales_data!D28="KERALA"),"IMPORTANT","OTHER STATE") -> OTHER STATE | K28: =IF(OR(Sales_data!G28>50000,Sales_data!I28>7000),"TOP","NORMAL") -> NORMAL | L28: =IF(OR(AND(Sales_data!G28>40000,Sales_data!I28>6000),Sales_data!H28>=10),"HIGH PRIORITY") -> FALSE | P28: Combine these three cells from Sales_data: | R28: Mobile | T28: ==SORT(FILTER(Sales_data!A2:I51,Sales_data!E2:E51="Electronics"),7,-1)
A29: =SUMIF(Sales_data!E2:E51,"ELECTRONICS",Sales_data!G2:G51) -> 765500 | E29: LOW | F29: LOW | G29: BULK | H29: =IF(AND(Sales_data!G29>30000,Sales_data!I29>5000),"HIGH","NRML") -> NRML | I29: =IF(AND(Sales_data!H29>=5,Sales_data!I29>=1000),"BEST","REGURAL") -> REGURAL | J29: =IF(OR(Sales_data!D29="TAMILNADU",Sales_data!D29="KERALA"),"IMPORTANT","OTHER STATE") -> OTHER STATE | K29: =IF(OR(Sales_data!G29>50000,Sales_data!I29>7000),"TOP","NORMAL") -> NORMAL | L29: =IF(OR(AND(Sales_data!G29>40000,Sales_data!I29>6000),Sales_data!H29>=10),"HIGH PRIORITY") -> HIGH PRIORITY | P29: Customer Name → C8 State → D8 Product → F8 Separate them with " | ". | R29: Mouse
E30: HIGH PROFIT | F30: GOOD SALES | G30: NORMAL | H30: =IF(AND(Sales_data!G30>30000,Sales_data!I30>5000),"HIGH","NRML") -> HIGH | I30: =IF(AND(Sales_data!H30>=5,Sales_data!I30>=1000),"BEST","REGURAL") -> REGURAL | J30: =IF(OR(Sales_data!D30="TAMILNADU",Sales_data!D30="KERALA"),"IMPORTANT","OTHER STATE") -> OTHER STATE | K30: =IF(OR(Sales_data!G30>50000,Sales_data!I30>7000),"TOP","NORMAL") -> NORMAL | L30: =IF(OR(AND(Sales_data!G30>40000,Sales_data!I30>6000),Sales_data!H30>=10),"HIGH PRIORITY") -> HIGH PRIORITY | P30: =_xlfn.TEXTJOIN(" | ",TRUE,Sales_data!C8,Sales_data!D28,Sales_data!F28) -> Suresh | Karnataka | Keyboard | R30: Keyboard | T30: Find all Product names where Sales > 50,000 and sort them from highest Sales → lowest Sales.
E31: HIGH PROFIT | F31: LOW | G31: NORMAL | H31: =IF(AND(Sales_data!G31>30000,Sales_data!I31>5000),"HIGH","NRML") -> NRML | I31: =IF(AND(Sales_data!H31>=5,Sales_data!I31>=1000),"BEST","REGURAL") -> REGURAL | J31: =IF(OR(Sales_data!D31="TAMILNADU",Sales_data!D31="KERALA"),"IMPORTANT","OTHER STATE") -> IMPORTANT | K31: =IF(OR(Sales_data!G31>50000,Sales_data!I31>7000),"TOP","NORMAL") -> NORMAL | L31: =IF(OR(AND(Sales_data!G31>40000,Sales_data!I31>6000),Sales_data!H31>=10),"HIGH PRIORITY") -> FALSE | R31: Monitor | T31: ==SORT(FILTER(Sales_data!A2:I51,Sales_data!G2:G51>50000),7,-1)
E32: HIGH PROFIT | F32: GOOD SALES | G32: NORMAL | H32: =IF(AND(Sales_data!G32>30000,Sales_data!I32>5000),"HIGH","NRML") -> HIGH | I32: =IF(AND(Sales_data!H32>=5,Sales_data!I32>=1000),"BEST","REGURAL") -> REGURAL | J32: =IF(OR(Sales_data!D32="TAMILNADU",Sales_data!D32="KERALA"),"IMPORTANT","OTHER STATE") -> OTHER STATE | K32: =IF(OR(Sales_data!G32>50000,Sales_data!I32>7000),"TOP","NORMAL") -> NORMAL | L32: =IF(OR(AND(Sales_data!G32>40000,Sales_data!I32>6000),Sales_data!H32>=10),"HIGH PRIORITY") -> HIGH PRIORITY | N32: Find the Price of Mobile. | P32: Order ID → A12 Customer Name → C12 Product → F12 Separator: " - ", combine | R32: Laptop
E33: LOW | F33: LOW | G33: BULK | H33: =IF(AND(Sales_data!G33>30000,Sales_data!I33>5000),"HIGH","NRML") -> NRML | I33: =IF(AND(Sales_data!H33>=5,Sales_data!I33>=1000),"BEST","REGURAL") -> REGURAL | J33: =IF(OR(Sales_data!D33="TAMILNADU",Sales_data!D33="KERALA"),"IMPORTANT","OTHER STATE") -> OTHER STATE | K33: =IF(OR(Sales_data!G33>50000,Sales_data!I33>7000),"TOP","NORMAL") -> NORMAL | L33: =IF(OR(AND(Sales_data!G33>40000,Sales_data!I33>6000),Sales_data!H33>=10),"HIGH PRIORITY") -> HIGH PRIORITY | N33: =HLOOKUP("Mobile",E54:I57,2,FALSE) -> 25000 | P33: =_xlfn.TEXTJOIN(" - ",TRUE,Sales_data!A12,Sales_data!C12,Sales_data!F12) -> ORD011 - Arun - Laptop | R33: Mobile | T33: Find all Furniture records where Profit > ₹5,000, and sort them by Profit highest → lowest.
A34: Q2. Find the total Profit for Furniture. | E34: HIGH PROFIT | F34: GOOD SALES | G34: NORMAL | H34: =IF(AND(Sales_data!G34>30000,Sales_data!I34>5000),"HIGH","NRML") -> HIGH | I34: =IF(AND(Sales_data!H34>=5,Sales_data!I34>=1000),"BEST","REGURAL") -> REGURAL | J34: =IF(OR(Sales_data!D34="TAMILNADU",Sales_data!D34="KERALA"),"IMPORTANT","OTHER STATE") -> OTHER STATE | K34: =IF(OR(Sales_data!G34>50000,Sales_data!I34>7000),"TOP","NORMAL") -> NORMAL | L34: =IF(OR(AND(Sales_data!G34>40000,Sales_data!I34>6000),Sales_data!H34>=10),"HIGH PRIORITY") -> FALSE | R34: Mouse | T34: ==SORT(FILTER(Sales_data!A2:I51,(Sales_data!E2:E51="Furniture")*(Sales_data!I2:I51>5000)),9,-1)
A35: =SUMIF(Sales_data!E2:E51,"FURNITURE",Sales_data!I2:I51) -> 56000 | E35: LOW | F35: LOW | G35: NORMAL | H35: =IF(AND(Sales_data!G35>30000,Sales_data!I35>5000),"HIGH","NRML") -> NRML | I35: =IF(AND(Sales_data!H35>=5,Sales_data!I35>=1000),"BEST","REGURAL") -> REGURAL | J35: =IF(OR(Sales_data!D35="TAMILNADU",Sales_data!D35="KERALA"),"IMPORTANT","OTHER STATE") -> IMPORTANT | K35: =IF(OR(Sales_data!G35>50000,Sales_data!I35>7000),"TOP","NORMAL") -> NORMAL | L35: =IF(OR(AND(Sales_data!G35>40000,Sales_data!I35>6000),Sales_data!H35>=10),"HIGH PRIORITY") -> FALSE | N35: Find the Quantity of Mouse | P35: TRIM | R35: Keyboard
E36: LOW | F36: LOW | G36: BULK | H36: =IF(AND(Sales_data!G36>30000,Sales_data!I36>5000),"HIGH","NRML") -> NRML | I36: =IF(AND(Sales_data!H36>=5,Sales_data!I36>=1000),"BEST","REGURAL") -> REGURAL | J36: =IF(OR(Sales_data!D36="TAMILNADU",Sales_data!D36="KERALA"),"IMPORTANT","OTHER STATE") -> OTHER STATE | K36: =IF(OR(Sales_data!G36>50000,Sales_data!I36>7000),"TOP","NORMAL") -> NORMAL | L36: =IF(OR(AND(Sales_data!G36>40000,Sales_data!I36>6000),Sales_data!H36>=10),"HIGH PRIORITY") -> FALSE | N36: =HLOOKUP("Mouse",E54:I57,3,FALSE) -> 10 | P36: =TRIM(#REF!) -> #REF! | R36: Monitor | T36: Find all Electronics records where Quantity > 5, and sort them by Quantity highest → lowest.
E37: LOW | F37: LOW | G37: BULK | H37: =IF(AND(Sales_data!G37>30000,Sales_data!I37>5000),"HIGH","NRML") -> NRML | I37: =IF(AND(Sales_data!H37>=5,Sales_data!I37>=1000),"BEST","REGURAL") -> REGURAL | J37: =IF(OR(Sales_data!D37="TAMILNADU",Sales_data!D37="KERALA"),"IMPORTANT","OTHER STATE") -> OTHER STATE | K37: =IF(OR(Sales_data!G37>50000,Sales_data!I37>7000),"TOP","NORMAL") -> NORMAL | L37: =IF(OR(AND(Sales_data!G37>40000,Sales_data!I37>6000),Sales_data!H37>=10),"HIGH PRIORITY") -> HIGH PRIORITY | N37: Find the Profit of Keyboard. | P37: Cleaned State | R37: Laptop | T37: ==SORT(FILTER(Sales_data!A2:I51,(Sales_data!E2:E51="Electronics")*(Sales_data!H2:H51>5)),8,-1)
E38: LOW | F38: LOW | G38: BULK | H38: =IF(AND(Sales_data!G38>30000,Sales_data!I38>5000),"HIGH","NRML") -> NRML | I38: =IF(AND(Sales_data!H38>=5,Sales_data!I38>=1000),"BEST","REGURAL") -> BEST | J38: =IF(OR(Sales_data!D38="TAMILNADU",Sales_data!D38="KERALA"),"IMPORTANT","OTHER STATE") -> OTHER STATE | K38: =IF(OR(Sales_data!G38>50000,Sales_data!I38>7000),"TOP","NORMAL") -> NORMAL | L38: =IF(OR(AND(Sales_data!G38>40000,Sales_data!I38>6000),Sales_data!H38>=10),"HIGH PRIORITY") -> FALSE | N38: =HLOOKUP("Keyboard",E54:I57,4,FALSE) -> 300 | P38: =TRIM(Sales_data!D2) -> Tamil Nadu | R38: Mobile
A39: 2️⃣ COUNTIF — Practice | E39: LOW | F39: LOW | G39: BULK | H39: =IF(AND(Sales_data!G39>30000,Sales_data!I39>5000),"HIGH","NRML") -> NRML | I39: =IF(AND(Sales_data!H39>=5,Sales_data!I39>=1000),"BEST","REGURAL") -> BEST | J39: =IF(OR(Sales_data!D39="TAMILNADU",Sales_data!D39="KERALA"),"IMPORTANT","OTHER STATE") -> IMPORTANT | K39: =IF(OR(Sales_data!G39>50000,Sales_data!I39>7000),"TOP","NORMAL") -> NORMAL | L39: =IF(OR(AND(Sales_data!G39>40000,Sales_data!I39>6000),Sales_data!H39>=10),"HIGH PRIORITY") -> FALSE | N39: Find the Quantity of Mobile. | R39: Mouse
A40: Q3. Count how many orders are from Tamil Nadu. | E40: HIGH PROFIT | F40: GOOD SALES | G40: NORMAL | H40: =IF(AND(Sales_data!G40>30000,Sales_data!I40>5000),"HIGH","NRML") -> HIGH | I40: =IF(AND(Sales_data!H40>=5,Sales_data!I40>=1000),"BEST","REGURAL") -> REGURAL | J40: =IF(OR(Sales_data!D40="TAMILNADU",Sales_data!D40="KERALA"),"IMPORTANT","OTHER STATE") -> OTHER STATE | K40: =IF(OR(Sales_data!G40>50000,Sales_data!I40>7000),"TOP","NORMAL") -> NORMAL | L40: =IF(OR(AND(Sales_data!G40>40000,Sales_data!I40>6000),Sales_data!H40>=10),"HIGH PRIORITY") -> FALSE | N40: =HLOOKUP("Mobile",E54:I57,3,FALSE) -> 5 | R40: Keyboard
...

Sheet Total Sales by Category.
A3: Category | B3: Sum of Sales
A4: Electronics | B4: 765500
A5: Furniture | B5: 280000
A6: Stationery | B6: 29100
A7: Grand Total | B7: 1074600
A10: PIVOT TABLE
G19: PIVOT CHART | M19: SLICERS

Sheet Total Profit by Category
A3: Category | B3: Sum of Profit
A4: Electronics | B4: 111700
A5: Furniture | B5: 56000
A6: Stationery | B6: 5820
A7: Grand Total | B7: 173520
A10: PIVOT TABLE
F18: PIVOT CHART | L18: SLICER

Sheet Total Sales by state
A3: State | B3: Sum of Sales
A4: Karnataka | B4: 332900
A5: Kerala | B5: 280000
A6: Tamil Nadu | B6: 432600
A7: Telangana | B7: 29100
A8: (blank)
A9: Grand Total | B9: 1074600
A11: PIVOT TABLE
O17: SLICER
H18: PIVOT CHART

Sheet Total sales by product
A3: Product | B3: Sum of Sales
A4: Laptop | B4: 330000
A5: Mobile | B5: 200000
A6: Monitor | B6: 188000
A7: Office Chair | B7: 100000
A8: Desk | B8: 99000
A9: Bookshelf | B9: 81000
A10: Keyboard | B10: 31500
A11: Notebook | B11: 17200
A12: Mouse | B12: 16000
A13: Pen | B13: 11900
A14: Grand Total | B14: 1074600
A17: PIVOT TABLE
N19: SLICER
H21: PIVOT CHART

Sheet Category-wise Sales & Profit
A3: Category | B3: Sum of Sales | C3: Sum of Profit
A4: Electronics | B4: 765500 | C4: 111700
A5: Furniture | B5: 280000 | C5: 56000
A6: Stationery | B6: 29100 | C6: 5820
A7: Grand Total | B7: 1074600 | C7: 173520
A11: PIVOT TABLE
O18: SLICER
H21: PIVOT CHART

Sheet Conditional Formatting
A1: Order_ID | B1: Order_Date | C1: Customer_Name | D1: State | E1: Category | F1: Product | G1: Sales | H1: Quantity | I1: Profit
A2: ORD001 | B2: 46027 | C2: Arun | D2: Tamil Nadu | E2: Electronics | F2: Laptop | G2: 55000 | H2: 2 | I2: 7000 | K2: Highlight Sales > ₹50,000
A3: ORD002 | B3: 46029 | C3: Priya | D3: Kerala | E3: Furniture | F3: Office Chair | G3: 12000 | H3: 3 | I3: 2400 | K3: Highlight Profit < ₹2,000
A4: ORD003 | B4: 46032 | C4: Ravi | D4: Karnataka | E4: Electronics | F4: Mobile | G4: 30000 | H4: 3 | I4: 4500 | K4: Top 10 Sales
A5: ORD004 | B5: 46035 | C5: Divya | D5: Telangana | E5: Stationery | F5: Notebook | G5: 2500 | H5: 10 | I5: 500 | K5: Data Bars IN SALES
A6: ORD005 | B6: 46038 | C6: Karthik | D6: Tamil Nadu | E6: Electronics | F6: Mouse | G6: 2400 | H6: 6 | I6: 480 | K6: Color Scales IN PROFIT
A7: ORD006 | B7: 46042 | C7: Meena | D7: Kerala | E7: Furniture | F7: Desk | G7: 18000 | H7: 2 | I7: 3600 | K7: Duplicate values IN CUSTOMER NAME
A8: ORD007 | B8: 46045 | C8: Suresh | D8: Karnataka | E8: Electronics | F8: Keyboard | G8: 4500 | H8: 5 | I8: 900
A9: ORD008 | B9: 46049 | C9: Anitha | D9: Telangana | E9: Stationery | F9: Pen | G9: 1200 | H9: 20 | I9: 240
A10: ORD009 | B10: 46055 | C10: Vimal | D10: Tamil Nadu | E10: Electronics | F10: Monitor | G10: 28000 | H10: 2 | I10: 4200
A11: ORD010 | B11: 46058 | C11: Kavya | D11: Kerala | E11: Furniture | F11: Bookshelf | G11: 15000 | H11: 2 | I11: 3000
A12: ORD011 | B12: 46061 | C12: Arun | D12: Karnataka | E12: Electronics | F12: Laptop | G12: 60000 | H12: 2 | I12: 8000
A13: ORD012 | B13: 46065 | C13: Priya | D13: Telangana | E13: Stationery | F13: Notebook | G13: 3000 | H13: 12 | I13: 600
A14: ORD013 | B14: 46068 | C14: Ravi | D14: Tamil Nadu | E14: Electronics | F14: Mobile | G14: 40000 | H14: 4 | I14: 6000
A15: ORD014 | B15: 46071 | C15: Divya | D15: Kerala | E15: Furniture | F15: Office Chair | G15: 16000 | H15: 4 | I15: 3200
A16: ORD015 | B16: 46074 | C16: Karthik | D16: Karnataka | E16: Electronics | F16: Mouse | G16: 3200 | H16: 8 | I16: 640
A17: ORD016 | B17: 46078 | C17: Meena | D17: Telangana | E17: Stationery | F17: Pen | G17: 1800 | H17: 30 | I17: 360
A18: ORD017 | B18: 46082 | C18: Suresh | D18: Tamil Nadu | E18: Electronics | F18: Keyboard | G18: 5400 | H18: 6 | I18: 1080
A19: ORD018 | B19: 46085 | C19: Anitha | D19: Kerala | E19: Furniture | F19: Desk | G19: 24000 | H19: 3 | I19: 4800
... A51: ORD050 | B51: 46195 | C51: Kavya | D51: Kerala | E51: Furniture | F51: Office Chair | G51: 28000 | H51: 7 | I51: 5600

Sheet FINAL Table
A1: Order_ID | B1: Order_Date | C1: Customer_Name | D1: State | E1: Category | F1: Product | G1: Sales | H1: Quantity | I1: Profit | K1: Total Sales
A2: ORD001 | B2: 46027 | C2: Arun | D2: Tamil Nadu | E2: Electronics | F2: Laptop | G2: 55000 | H2: 2 | I2: 7000 | K2: =SUM(G2:G51) -> 1074600
A3: ORD002 | B3: 46029 | C3: Priya | D3: Kerala | E3: Furniture | F3: Office Chair | G3: 12000 | H3: 3 | I3: 2400 | K3: Total Profit
A4: ORD003 | B4: 46032 | C4: Ravi | D4: Karnataka | E4: Electronics | F4: Mobile | G4: 30000 | H4: 3 | I4: 4500 | K4: =SUM(I2:I51) -> 173520
A5: ORD004 | B5: 46035 | C5: Divya | D5: Telangana | E5: Stationery | F5: Notebook | G5: 2500 | H5: 10 | I5: 500 | K5: Total Quantity
A6: ORD005 | B6: 46038 | C6: Karthik | D6: Tamil Nadu | E6: Electronics | F6: Mouse | G6: 2400 | H6: 6 | I6: 480 | K6: =SUM(H2:H51) -> 429
A7: ORD006 | B7: 46042 | C7: Meena | D7: Kerala | E7: Furniture | F7: Desk | G7: 18000 | H7: 2 | I7: 3600 | K7: Average Sales
A8: ORD007 | B8: 46045 | C8: Suresh | D8: Karnataka | E8: Electronics | F8: Keyboard | G8: 4500 | H8: 5 | I8: 900 | K8: =AVERAGE(G2:G51) -> 21492
A9: ORD008 | B9: 46049 | C9: Anitha | D9: Telangana | E9: Stationery | F9: Pen | G9: 1200 | H9: 20 | I9: 240 | K9: Total Orders
A10: ORD009 | B10: 46055 | C10: Vimal | D10: Tamil Nadu | E10: Electronics | F10: Monitor | G10: 28000 | H10: 2 | I10: 4200 | K10: =COUNTA(A2:A51) -> 50
A11: ORD010 | B11: 46058 | C11: Kavya | D11: Kerala | E11: Furniture | F11: Bookshelf | G11: 15000 | H11: 2 | I11: 3000 | K11: Highest Sales
A12: ORD011 | B12: 46061 | C12: Arun | D12: Karnataka | E12: Electronics | F12: Laptop | G12: 60000 | H12: 2 | I12: 8000 | K12: =MAX(G2:G51) -> 90000
A13: ORD012 | B13: 46065 | C13: Priya | D13: Telangana | E13: Stationery | F13: Notebook | G13: 3000 | H13: 12 | I13: 600 | K13: Highest Profit
A14: ORD013 | B14: 46068 | C14: Ravi | D14: Tamil Nadu | E14: Electronics | F14: Mobile | G14: 40000 | H14: 4 | I14: 6000 | K14: =MAX(I2:I51) -> 12000
A15: ORD014 | B15: 46071 | C15: Divya | D15: Kerala | E15: Furniture | F15: Office Chair | G15: 16000 | H15: 4 | I15: 3200
A16: ORD015 | B16: 46074 | C16: Karthik | D16: Karnataka | E16: Electronics | F16: Mouse | G16: 3200 | H16: 8 | I16: 640
A17: ORD016 | B17: 46078 | C17: Meena | D17: Telangana | E17: Stationery | F17: Pen | G17: 1800 | H17: 30 | I17: 360
A18: ORD017 | B18: 46082 | C18: Suresh | D18: Tamil Nadu | E18: Electronics | F18: Keyboard | G18: 5400 | H18: 6 | I18: 1080
A19: ORD018 | B19: 46085 | C19: Anitha | D19: Kerala | E19: Furniture | F19: Desk | G19: 24000 | H19: 3 | I19: 4800
A20: ORD019 | B20: 46089 | C20: Vimal | D20: Karnataka | E20: Electronics | F20: Monitor | G20: 35000 | H20: 2 | I20: 5250
A21: ORD020 | B21: 46093 | C21: Kavya | D21: Telangana | E21: Stationery | F21: Notebook | G21: 2200 | H21: 9 | I21: 440
A22: ORD021 | B22: 46096 | C22: Arun | D22: Tamil Nadu | E22: Electronics | F22: Laptop | G22: 75000 | H22: 3 | I22: 10000
A23: ORD022 | B23: 46099 | C23: Priya | D23: Kerala | E23: Furniture | F23: Bookshelf | G23: 22000 | H23: 3 | I23: 4400
A24: ORD023 | B24: 46102 | C24: Ravi | D24: Karnataka | E24: Electronics | F24: Mobile | G24: 50000 | H24: 5 | I24: 7500
A25: ORD024 | B25: 46106 | C25: Divya | D25: Telangana | E25: Stationery | F25: Pen | G25: 2500 | H25: 40 | I25: 500
A26: ORD025 | B26: 46109 | C26: Karthik | D26: Tamil Nadu | E26: Electronics | F26: Mouse | G26: 4000 | H26: 10 | I26: 800
... A51: ORD050 | B51: 46195 | C51: Kavya | D51: Kerala | E51: Furniture | F51: Office Chair | G51: 28000 | H51: 7 | I51: 5600

Sheet FINAL Pivot Tables
A3: State | B3: Sum of Sales | D3: Product | E3: Sum of Sales | G3: Customer_Name | H3: Sum of Sales | J3: Category | K3: Sum of Sales
A4: Karnataka | B4: 332900 | D4: Bookshelf | E4: 81000 | G4: Anitha | H4: 55500 | J4: Electronics | K4: 765500
A5: Kerala | B5: 280000 | D5: Desk | E5: 99000 | G5: Arun | H5: 330000 | J5: Furniture | K5: 280000
A6: Tamil Nadu | B6: 432600 | D6: Keyboard | E6: 31500 | G6: Divya | H6: 43200 | J6: Stationery | K6: 29100
A7: Telangana | B7: 29100 | D7: Laptop | E7: 330000 | G7: Karthik | H7: 16000 | J7: Grand Total | K7: 1074600
A8: Grand Total | B8: 1074600 | D8: Mobile | E8: 200000 | G8: Kavya | H8: 77300
D9: Monitor | E9: 188000 | G9: Meena | H9: 67600
D10: Mouse | E10: 16000 | G10: Priya | H10: 65500
D11: Notebook | E11: 17200 | G11: Ravi | H11: 200000
D12: Office Chair | E12: 100000 | G12: Suresh | H12: 31500
D13: Pen | E13: 11900 | G13: Vimal | H13: 188000
D14: Grand Total | E14: 1074600 | G14: Grand Total | H14: 1074600
